Workbook

Sheet Dashboard
A1: Vendor Payment & Expense Dashboard
A4: Select Month: | B4: All
A6: Total Spend (₹) | C6: Total Outstanding (Pending+Overdue) (₹) | E6: Overdue Invoice Count | G6: % Paid
A7: {=SUMPRODUCT((IF($B$4="All",1,Raw_Data!$P$2:$P$104=MATCH($B$4,{"Jan","Feb","Mar","Apr","May","Jun"},0)))*Raw_Data!$H$2:$H$104)} -> 5952969.7 | C7: {=SUMPRODUCT((IF($B$4="All",1,Raw_Data!$P$2:$P$104=MATCH($B$4,{"Jan","Feb","Mar","Apr","May","Jun"},0)))*((Raw_Data!$I$2:$I$104="Pending")+(Raw_Data!$I$2:$I$104="Overdue"))*Raw_Data!$H$2:$H$104)} -> 1607513.2 | E7: {=SUMPRODUCT((IF($B$4="All",1,Raw_Data!$P$2:$P$104=MATCH($B$4,{"Jan","Feb","Mar","Apr","May","Jun"},0)))*(Raw_Data!$I$2:$I$104="Overdue"))} -> 19 | G7: {=SUMPRODUCT((IF($B$4="All",1,Raw_Data!$P$2:$P$104=MATCH($B$4,{"Jan","Feb","Mar","Apr","May","Jun"},0)))*(Raw_Data!$I$2:$I$104="Paid"))/SUMPRODUCT((IF($B$4="All",1,Raw_Data!$P$2:$P$104=MATCH($B$4,{"Jan","Feb","Mar","Apr","May","Jun"},0)))*(ROW(Raw_Data!$H$2:$H$104)>0))} -> 0.69902913
A9: Live Pivot — Category x Payment Status (auto-updates with month filter above)
A10: Category | B10: Paid | C10: Pending | D10: Overdue | E10: Grand Total
A11: =Summary!A62 -> Housekeeping | B11: =Summary!B62 -> 383814.6 | C11: =Summary!C62 -> 107784.8 | D11: =Summary!D62 -> 176514.52 | E11: =Summary!E62 -> 668113.92
A12: =Summary!A63 -> Insurance | B12: =Summary!B63 -> 192487.37 | C12: =Summary!C63 -> 127640.72 | D12: =Summary!D63 -> 69289.95 | E12: =Summary!E63 -> 389418.04
A13: =Summary!A64 -> Landscaping | B13: =Summary!B64 -> 458479.15 | C13: =Summary!C64 -> 90106 | D13: =Summary!D64 -> 11947.51 | E13: =Summary!E64 -> 560532.66
A14: =Summary!A65 -> Maintenance | B14: =Summary!B65 -> 927746 | C14: =Summary!C65 -> 29400.73 | D14: =Summary!D65 -> 202823.68 | E14: =Summary!E65 -> 1159970.4
A15: =Summary!A66 -> Marketing | B15: =Summary!B66 -> 119719.48 | C15: =Summary!C66 -> 128668.63 | D15: =Summary!D66 -> 18233.18 | E15: =Summary!E66 -> 266621.29
A16: =Summary!A67 -> Office Supplies | B16: =Summary!B67 -> 226557.38 | C16: =Summary!C67 -> 0 | D16: =Summary!D67 -> 31378.58 | E16: =Summary!E67 -> 257935.96
A17: =Summary!A68 -> Professional Fees | B17: =Summary!B68 -> 652777.28 | C17: =Summary!C68 -> 158639.52 | D17: =Summary!D68 -> 111661.83 | E17: =Summary!E68 -> 923078.63
A18: =Summary!A69 -> Repairs | B18: =Summary!B69 -> 504788.32 | C18: =Summary!C69 -> 0 | D18: =Summary!D69 -> 61735.58 | E18: =Summary!E69 -> 566523.9
A19: =Summary!A70 -> Security | B19: =Summary!B70 -> 390893.44 | C19: =Summary!C70 -> 53441.39 | D19: =Summary!D70 -> 93918.83 | E19: =Summary!E70 -> 538253.66
A20: =Summary!A71 -> Utilities | B20: =Summary!B71 -> 488193.49 | C20: =Summary!C71 -> 102342.02 | D20: =Summary!D71 -> 31985.69 | E20: =Summary!E71 -> 622521.2
A21: =Summary!A72 -> Grand Total | B21: =Summary!B72 -> 4345456.5 | C21: =Summary!C72 -> 798023.81 | D21: =Summary!D72 -> 809489.35 | E21: =Summary!E72 -> 5952969.7
A23: Both charts and the pivot above now recompute live from the month dropdown (cell B4).
A28: Build steps for you to complete by hand (see project guide): PivotTable from Raw_Data, and Power Query merge of the two raw export files.

Sheet Assumptions
A1: Assumptions & Notes
A3: GST Rate Assumed | B3: 0.18
A4: Large Invoice Threshold (₹) | B4: 70000
A5: Dashboard 'As Of' Date | B5: 2026-06-30

Sheet Vendor_Master
A1: Vendor_Name | B1: Category | C1: Payment_Terms_Days | D1: Contact_Person | E1: Onboarded_Date
A2: Shree Maintenance Services | B2: Maintenance | C2: 30 | D2: Contact 1 | E2: 2024-04-12
A3: Apex Security Solutions | B3: Security | C3: 30 | D3: Contact 2 | E3: 2025-03-11
A4: Clean & Clear Housekeeping | B4: Housekeeping | C4: 15 | D4: Contact 3 | E4: 2024-12-14
A5: GreenScape Landscaping | B5: Landscaping | C5: 30 | D5: Contact 4 | E5: 2024-09-27
A6: Delhi Power Utilities Pvt Ltd | B6: Utilities | C6: 15 | D6: Contact 5 | E6: 2024-04-16
A7: Reliable Repairs Co | B7: Repairs | C7: 30 | D7: Contact 6 | E7: 2024-03-12
A8: Capital Insurance Brokers | B8: Insurance | C8: 45 | D8: Contact 7 | E8: 2024-07-07
A9: BrightWay Office Supplies | B9: Office Supplies | C9: 15 | D9: Contact 8 | E9: 2024-01-21
A10: Nexus Professional Consultants | B10: Professional Fees | C10: 45 | D10: Contact 9 | E10: 2024-04-12
A11: UrbanEdge Marketing | B11: Marketing | C11: 30 | D11: Contact 10 | E11: 2024-05-01
A12: SafeGuard Fire & Safety | B12: Maintenance | C12: 30 | D12: Contact 11 | E12: 2025-04-11
A13: Crystal Water Treatment | B13: Utilities | C13: 15 | D13: Contact 12 | E13: 2024-08-02

Sheet Raw_Data
A1: Invoice_No | B1: Vendor_Name | C1: Property_Unit | D1: Invoice_Date | E1: Due_Date | F1: Amount | G1: GST_Amount | H1: Total_Amount | I1: Payment_Status | J1: Payment_Date | K1: Terms_VLOOKUP | L1: Terms_XLOOKUP | M1: Terms_INDEXMATCH | N1: Large_Invoice_Flag | O1: Category_Lookup | P1: Month_No
A2: INV-1001 | B2: Apex Security Solutions | C2: Tower B | D2: 2026-01-01 | E2: 2026-01-31 | F2: 72514.89 | G2: 13052.68 | H2: 85567.57 | I2: Paid | J2: 2026-01-04 | K2: =VLOOKUP(B2,Vendor_Master!$A:$C,3,FALSE()) -> 30 | L2: =_xlfn.XLOOKUP(B2,Vendor_Master!A:A,Vendor_Master!C:C) -> 30 | M2: =INDEX(Vendor_Master!$C:$C,MATCH(B2,Vendor_Master!$A:$A,0)) -> 30 | N2: =IF(H2>Assumptions!$B$4,"Large","") -> Large | O2: =INDEX(Vendor_Master!$B:$B,MATCH(B2,Vendor_Master!$A:$A,0)) -> Security | P2: =MONTH(D2) -> 1
A3: INV-1002 | B3: SafeGuard Fire & Safety | C3: Tower A | D3: 2026-01-24 | E3: 2026-02-23 | F3: 85619.62 | G3: 15411.53 | H3: 101031.15 | I3: Paid | J3: 2026-01-25 | K3: =VLOOKUP(B3,Vendor_Master!$A:$C,3,FALSE()) -> 30 | L3: =_xlfn.XLOOKUP(B3,Vendor_Master!A:A,Vendor_Master!C:C) -> 30 | M3: =INDEX(Vendor_Master!$C:$C,MATCH(B3,Vendor_Master!$A:$A,0)) -> 30 | N3: =IF(H3>Assumptions!$B$4,"Large","") -> Large | O3: =INDEX(Vendor_Master!$B:$B,MATCH(B3,Vendor_Master!$A:$A,0)) -> Maintenance | P3: =MONTH(D3) -> 1
A4: INV-1003 | B4: Shree Maintenance Services | C4: Tower A | D4: 2026-01-03 | E4: 2026-02-02 | F4: 27021.5 | G4: 4863.87 | H4: 31885.37 | I4: Paid | J4: 2026-02-03 | K4: =VLOOKUP(B4,Vendor_Master!$A:$C,3,FALSE()) -> 30 | L4: =_xlfn.XLOOKUP(B4,Vendor_Master!A:A,Vendor_Master!C:C) -> 30 | M4: =INDEX(Vendor_Master!$C:$C,MATCH(B4,Vendor_Master!$A:$A,0)) -> 30 | N4: =IF(H4>Assumptions!$B$4,"Large","") | O4: =INDEX(Vendor_Master!$B:$B,MATCH(B4,Vendor_Master!$A:$A,0)) -> Maintenance | P4: =MONTH(D4) -> 1
A5: INV-1004 | B5: Capital Insurance Brokers | C5: Commercial Block | D5: 2026-01-08 | E5: 2026-02-22 | F5: 47081.19 | G5: 8474.61 | H5: 55555.8 | I5: Overdue | K5: =VLOOKUP(B5,Vendor_Master!$A:$C,3,FALSE()) -> 45 | L5: =_xlfn.XLOOKUP(B5,Vendor_Master!A:A,Vendor_Master!C:C) -> 45 | M5: =INDEX(Vendor_Master!$C:$C,MATCH(B5,Vendor_Master!$A:$A,0)) -> 45 | N5: =IF(H5>Assumptions!$B$4,"Large","") | O5: =INDEX(Vendor_Master!$B:$B,MATCH(B5,Vendor_Master!$A:$A,0)) -> Insurance | P5: =MONTH(D5) -> 1
A6: INV-1005 | B6: Shree Maintenance Services | C6: Retail Plaza | D6: 2026-01-25 | E6: 2026-02-24 | F6: 78106.27 | G6: 14059.13 | H6: 92165.4 | I6: Paid | J6: 2026-01-31 | K6: =VLOOKUP(B6,Vendor_Master!$A:$C,3,FALSE()) -> 30 | L6: =_xlfn.XLOOKUP(B6,Vendor_Master!A:A,Vendor_Master!C:C) -> 30 | M6: =INDEX(Vendor_Master!$C:$C,MATCH(B6,Vendor_Master!$A:$A,0)) -> 30 | N6: =IF(H6>Assumptions!$B$4,"Large","") -> Large | O6: =INDEX(Vendor_Master!$B:$B,MATCH(B6,Vendor_Master!$A:$A,0)) -> Maintenance | P6: =MONTH(D6) -> 1
A7: INV-1006 | B7: GreenScape Landscaping | C7: Tower A | D7: 2026-01-25 | E7: 2026-02-24 | F7: 37283.73 | G7: 6711.07 | H7: 43994.8 | I7: Paid | J7: 2026-02-13 | K7: =VLOOKUP(B7,Vendor_Master!$A:$C,3,FALSE()) -> 30 | L7: =_xlfn.XLOOKUP(B7,Vendor_Master!A:A,Vendor_Master!C:C) -> 30 | M7: =INDEX(Vendor_Master!$C:$C,MATCH(B7,Vendor_Master!$A:$A,0)) -> 30 | N7: =IF(H7>Assumptions!$B$4,"Large","") | O7: =INDEX(Vendor_Master!$B:$B,MATCH(B7,Vendor_Master!$A:$A,0)) -> Landscaping | P7: =MONTH(D7) -> 1
A8: INV-1007 | B8: Reliable Repairs Co | C8: Tower A | D8: 2026-01-20 | E8: 2026-02-19 | F8: 31013.32 | G8: 5582.4 | H8: 36595.72 | I8: Paid | J8: 2026-02-20 | K8: =VLOOKUP(B8,Vendor_Master!$A:$C,3,FALSE()) -> 30 | L8: =_xlfn.XLOOKUP(B8,Vendor_Master!A:A,Vendor_Master!C:C) -> 30 | M8: =INDEX(Vendor_Master!$C:$C,MATCH(B8,Vendor_Master!$A:$A,0)) -> 30 | N8: =IF(H8>Assumptions!$B$4,"Large","") | O8: =INDEX(Vendor_Master!$B:$B,MATCH(B8,Vendor_Master!$A:$A,0)) -> Repairs | P8: =MONTH(D8) -> 1
A9: INV-1008 | B9: Apex Security Solutions | C9: Commercial Block | D9: 2026-01-13 | E9: 2026-02-12 | F9: 14855.62 | G9: 2674.01 | H9: 17529.63 | I9: Overdue | K9: =VLOOKUP(B9,Vendor_Master!$A:$C,3,FALSE()) -> 30 | L9: =_xlfn.XLOOKUP(B9,Vendor_Master!A:A,Vendor_Master!C:C) -> 30 | M9: =INDEX(Vendor_Master!$C:$C,MATCH(B9,Vendor_Master!$A:$A,0)) -> 30 | N9: =IF(H9>Assumptions!$B$4,"Large","") | O9: =INDEX(Vendor_Master!$B:$B,MATCH(B9,Vendor_Master!$A:$A,0)) -> Security | P9: =MONTH(D9) -> 1
A10: INV-1009 | B10: UrbanEdge Marketing | C10: Tower B | D10: 2026-01-28 | E10: 2026-02-27 | F10: 39462.25 | G10: 7103.2 | H10: 46565.45 | I10: Paid | J10: 2026-01-29 | K10: =VLOOKUP(B10,Vendor_Master!$A:$C,3,FALSE()) -> 30 | L10: =_xlfn.XLOOKUP(B10,Vendor_Master!A:A,Vendor_Master!C:C) -> 30 | M10: =INDEX(Vendor_Master!$C:$C,MATCH(B10,Vendor_Master!$A:$A,0)) -> 30 | N10: =IF(H10>Assumptions!$B$4,"Large","") | O10: =INDEX(Vendor_Master!$B:$B,MATCH(B10,Vendor_Master!$A:$A,0)) -> Marketing | P10: =MONTH(D10) -> 1
A11: INV-1010 | B11: SafeGuard Fire & Safety | C11: Tower A | D11: 2026-01-08 | E11: 2026-02-07 | F11: 75256.95 | G11: 13546.25 | H11: 88803.2 | I11: Overdue | K11: =VLOOKUP(B11,Vendor_Master!$A:$C,3,FALSE()) -> 30 | L11: =_xlfn.XLOOKUP(B11,Vendor_Master!A:A,Vendor_Master!C:C) -> 30 | M11: =INDEX(Vendor_Master!$C:$C,MATCH(B11,Vendor_Master!$A:$A,0)) -> 30 | N11: =IF(H11>Assumptions!$B$4,"Large","") -> Large | O11: =INDEX(Vendor_Master!$B:$B,MATCH(B11,Vendor_Master!$A:$A,0)) -> Maintenance | P11: =MONTH(D11) -> 1
A12: INV-1011 | B12: Apex Security Solutions | C12: Commercial Block | D12: 2026-01-13 | E12: 2026-02-12 | F12: 32183.7 | G12: 5793.07 | H12: 37976.77 | I12: Paid | J12: 2026-02-01 | K12: =VLOOKUP(B12,Vendor_Master!$A:$C,3,FALSE()) -> 30 | L12: =_xlfn.XLOOKUP(B12,Vendor_Master!A:A,Vendor_Master!C:C) -> 30 | M12: =INDEX(Vendor_Master!$C:$C,MATCH(B12,Vendor_Master!$A:$A,0)) -> 30 | N12: =IF(H12>Assumptions!$B$4,"Large","") | O12: =INDEX(Vendor_Master!$B:$B,MATCH(B12,Vendor_Master!$A:$A,0)) -> Security | P12: =MONTH(D12) -> 1
A13: INV-1012 | B13: SafeGuard Fire & Safety | C13: Tower A | D13: 2026-01-23 | E13: 2026-02-22 | F13: 69058.37 | G13: 12430.51 | H13: 81488.88 | I13: Paid | J13: 2026-01-30 | K13: =VLOOKUP(B13,Vendor_Master!$A:$C,3,FALSE()) -> 30 | L13: =_xlfn.XLOOKUP(B13,Vendor_Master!A:A,Vendor_Master!C:C) -> 30 | M13: =INDEX(Vendor_Master!$C:$C,MATCH(B13,Vendor_Master!$A:$A,0)) -> 30 | N13: =IF(H13>Assumptions!$B$4,"Large","") -> Large | O13: =INDEX(Vendor_Master!$B:$B,MATCH(B13,Vendor_Master!$A:$A,0)) -> Maintenance | P13: =MONTH(D13) -> 1
A14: INV-1013 | B14: Nexus Professional Consultants | C14: Retail Plaza | D14: 2026-02-07 | E14: 2026-03-24 | F14: 29298.55 | G14: 5273.74 | H14: 34572.29 | I14: Paid | J14: 2026-03-16 | K14: =VLOOKUP(B14,Vendor_Master!$A:$C,3,FALSE()) -> 45 | L14: =_xlfn.XLOOKUP(B14,Vendor_Master!A:A,Vendor_Master!C:C) -> 45 | M14: =INDEX(Vendor_Master!$C:$C,MATCH(B14,Vendor_Master!$A:$A,0)) -> 45 | N14: =IF(H14>Assumptions!$B$4,"Large","") | O14: =INDEX(Vendor_Master!$B:$B,MATCH(B14,Vendor_Master!$A:$A,0)) -> Professional Fees | P14: =MONTH(D14) -> 2
A15: INV-1014 | B15: Crystal Water Treatment | C15: Commercial Block | D15: 2026-02-01 | E15: 2026-02-16 | F15: 27106.52 | G15: 4879.17 | H15: 31985.69 | I15: Overdue | K15: =VLOOKUP(B15,Vendor_Master!$A:$C,3,FALSE()) -> 15 | L15: =_xlfn.XLOOKUP(B15,Vendor_Master!A:A,Vendor_Master!C:C) -> 15 | M15: =INDEX(Vendor_Master!$C:$C,MATCH(B15,Vendor_Master!$A:$A,0)) -> 15 | N15: =IF(H15>Assumptions!$B$4,"Large","") | O15: =INDEX(Vendor_Master!$B:$B,MATCH(B15,Vendor_Master!$A:$A,0)) -> Utilities | P15: =MONTH(D15) -> 2
A16: INV-1015 | B16: Shree Maintenance Services | C16: Commercial Block | D16: 2026-01-22 | E16: 2026-02-21 | F16: 79496.83 | G16: 14309.43 | H16: 93806.26 | I16: Paid | J16: 2026-01-23 | K16: =VLOOKUP(B16,Vendor_Master!$A:$C,3,FALSE()) -> 30 | L16: =_xlfn.XLOOKUP(B16,Vendor_Master!A:A,Vendor_Master!C:C) -> 30 | M16: =INDEX(Vendor_Master!$C:$C,MATCH(B16,Vendor_Master!$A:$A,0)) -> 30 | N16: =IF(H16>Assumptions!$B$4,"Large","") -> Large | O16: =INDEX(Vendor_Master!$B:$B,MATCH(B16,Vendor_Master!$A:$A,0)) -> Maintenance | P16: =MONTH(D16) -> 1
A17: INV-1016 | B17: GreenScape Landscaping | C17: Commercial Block | D17: 2026-02-02 | E17: 2026-03-04 | F17: 84243.98 | G17: 15163.92 | H17: 99407.9 | I17: Paid | J17: 2026-03-02 | K17: =VLOOKUP(B17,Vendor_Master!$A:$C,3,FALSE()) -> 30 | L17: =_xlfn.XLOOKUP(B17,Vendor_Master!A:A,Vendor_Master!C:C) -> 30 | M17: =INDEX(Vendor_Master!$C:$C,MATCH(B17,Vendor_Master!$A:$A,0)) -> 30 | N17: =IF(H17>Assumptions!$B$4,"Large","") -> Large | O17: =INDEX(Vendor_Master!$B:$B,MATCH(B17,Vendor_Master!$A:$A,0)) -> Landscaping | P17: =MONTH(D17) -> 2
A18: INV-1017 | B18: Capital Insurance Brokers | C18: Commercial Block | D18: 2026-02-04 | E18: 2026-03-21 | F18: 47920.11 | G18: 8625.62 | H18: 56545.73 | I18: Paid | J18: 2026-03-20 | K18: =VLOOKUP(B18,Vendor_Master!$A:$C,3,FALSE()) -> 45 | L18: =_xlfn.XLOOKUP(B18,Vendor_Master!A:A,Vendor_Master!C:C) -> 45 | M18: =INDEX(Vendor_Master!$C:$C,MATCH(B18,Vendor_Master!$A:$A,0)) -> 45 | N18: =IF(H18>Assumptions!$B$4,"Large","") | O18: =INDEX(Vendor_Master!$B:$B,MATCH(B18,Vendor_Master!$A:$A,0)) -> Insurance | P18: =MONTH(D18) -> 2
A19: INV-1018 | B19: Nexus Professional Consultants | C19: Retail Plaza | D19: 2026-02-01 | E19: 2026-03-18 | F19: 30858.52 | G19: 5554.53 | H19: 36413.05 | I19: Overdue | K19: =VLOOKUP(B19,Vendor_Master!$A:$C,3,FALSE()) -> 45 | L19: =_xlfn.XLOOKUP(B19,Vendor_Master!A:A,Vendor_Master!C:C) -> 45 | M19: =INDEX(Vendor_Master!$C:$C,MATCH(B19,Vendor_Master!$A:$A,0)) -> 45 | N19: =IF(H19>Assumptions!$B$4,"Large","") | O19: =INDEX(Vendor_Master!$B:$B,MATCH(B19,Vendor_Master!$A:$A,0)) -> Professional Fees | P19: =MONTH(D19) -> 2
A20: INV-1019 | B20: Reliable Repairs Co | C20: Tower B | D20: 2026-02-05 | E20: 2026-03-07 | F20: 94767.34 | G20: 17058.12 | H20: 111825.46 | I20: Paid | J20: 2026-02-07 | K20: =VLOOKUP(B20,Vendor_Master!$A:$C,3,FALSE()) -> 30 | L20: =_xlfn.XLOOKUP(B20,Vendor_Master!A:A,Vendor_Master!C:C) -> 30 | M20: =INDEX(Vendor_Master!$C:$C,MATCH(B20,Vendor_Master!$A:$A,0)) -> 30 | N20: =IF(H20>Assumptions!$B$4,"Large","") -> Large | O20: =INDEX(Vendor_Master!$B:$B,MATCH(B20,Vendor_Master!$A:$A,0)) -> Repairs | P20: =MONTH(D20) -> 2
A21: INV-1020 | B21: Shree Maintenance Services | C21: Tower B | D21: 2026-02-25 | E21: 2026-03-27 | F21: 17539.47 | G21: 3157.1 | H21: 20696.57 | I21: Overdue | K21: =VLOOKUP(B21,Vendor_Master!$A:$C,3,FALSE()) -> 30 | L21: =_xlfn.XLOOKUP(B21,Vendor_Master!A:A,Vendor_Master!C:C) -> 30 | M21: =INDEX(Vendor_Master!$C:$C,MATCH(B21,Vendor_Master!$A:$A,0)) -> 30 | N21: =IF(H21>Assumptions!$B$4,"Large","") | O21: =INDEX(Vendor_Master!$B:$B,MATCH(B21,Vendor_Master!$A:$A,0)) -> Maintenance | P21: =MONTH(D21) -> 2
A22: INV-1021 | B22: Capital Insurance Brokers | C22: Retail Plaza | D22: 2026-02-17 | E22: 2026-04-03 | F22: 13526.91 | G22: 2434.84 | H22: 15961.75 | I22: Paid | J22: 2026-03-15 | K22: =VLOOKUP(B22,Vendor_Master!$A:$C,3,FALSE()) -> 45 | L22: =_xlfn.XLOOKUP(B22,Vendor_Master!A:A,Vendor_Master!C:C) -> 45 | M22: =INDEX(Vendor_Master!$C:$C,MATCH(B22,Vendor_Master!$A:$A,0)) -> 45 | N22: =IF(H22>Assumptions!$B$4,"Large","") | O22: =INDEX(Vendor_Master!$B:$B,MATCH(B22,Vendor_Master!$A:$A,0)) -> Insurance | P22: =MONTH(D22) -> 2
A23: INV-1022 | B23: Nexus Professional Consultants | C23: Tower A | D23: 2026-02-06 | E23: 2026-03-23 | F23: 92483.82 | G23: 16647.09 | H23: 109130.91 | I23: Paid | J23: 2026-02-10 | K23: =VLOOKUP(B23,Vendor_Master!$A:$C,3,FALSE()) -> 45 | L23: =_xlfn.XLOOKUP(B23,Vendor_Master!A:A,Vendor_Master!C:C) -> 45 | M23: =INDEX(Vendor_Master!$C:$C,MATCH(B23,Vendor_Master!$A:$A,0)) -> 45 | N23: =IF(H23>Assumptions!$B$4,"Large","") -> Large | O23: =INDEX(Vendor_Master!$B:$B,MATCH(B23,Vendor_Master!$A:$A,0)) -> Professional Fees | P23: =MONTH(D23) -> 2
A24: INV-1023 | B24: SafeGuard Fire & Safety | C24: Commercial Block | D24: 2026-02-15 | E24: 2026-03-17 | F24: 73326.37 | G24: 13198.75 | H24: 86525.12 | I24: Paid | J24: 2026-03-11 | K24: =VLOOKUP(B24,Vendor_Master!$A:$C,3,FALSE()) -> 30 | L24: =_xlfn.XLOOKUP(B24,Vendor_Master!A:A,Vendor_Master!C:C) -> 30 | M24: =INDEX(Vendor_Master!$C:$C,MATCH(B24,Vendor_Master!$A:$A,0)) -> 30 | N24: =IF(H24>Assumptions!$B$4,"Large","") -> Large | O24: =INDEX(Vendor_Master!$B:$B,MATCH(B24,Vendor_Master!$A:$A,0)) -> Maintenance | P24: =MONTH(D24) -> 2
A25: INV-1024 | B25: Clean & Clear Housekeeping | C25: Commercial Block | D25: 2026-02-12 | E25: 2026-02-27 | F25: 8282.34 | G25: 1490.82 | H25: 9773.16 | I25: Overdue | K25: =VLOOKUP(B25,Vendor_Master!$A:$C,3,FALSE()) -> 15 | L25: =_xlfn.XLOOKUP(B25,Vendor_Master!A:A,Vendor_Master!C:C) -> 15 | M25: =INDEX(Vendor_Master!$C:$C,MATCH(B25,Vendor_Master!$A:$A,0)) -> 15 | N25: =IF(H25>Assumptions!$B$4,"Large","") | O25: =INDEX(Vendor_Master!$B:$B,MATCH(B25,Vendor_Master!$A:$A,0)) -> Housekeeping | P25: =MONTH(D25) -> 2
A26: INV-1025 | B26: Clean & Clear Housekeeping | C26: Commercial Block | D26: 2026-02-14 | E26: 2026-03-01 | F26: 87398.62 | G26: 15731.75 | H26: 103130.37 | I26: Overdue | K26: =VLOOKUP(B26,Vendor_Master!$A:$C,3,FALSE()) -> 15 | L26: =_xlfn.XLOOKUP(B26,Vendor_Master!A:A,Vendor_Master!C:C) -> 15 | M26: =INDEX(Vendor_Master!$C:$C,MATCH(B26,Vendor_Master!$A:$A,0)) -> 15 | N26: =IF(H26>Assumptions!$B$4,"Large","") -> Large | O26: =INDEX(Vendor_Master!$B:$B,MATCH(B26,Vendor_Master!$A:$A,0)) -> Housekeeping | P26: =MONTH(D26) -> 2
A27: INV-1026 | B27: Nexus Professional Consultants | C27: Commercial Block | D27: 2026-02-17 | E27: 2026-04-03 | F27: 25305.27 | G27: 4554.95 | H27: 29860.22 | I27: Overdue | K27: =VLOOKUP(B27,Vendor_Master!$A:$C,3,FALSE()) -> 45 | L27: =_xlfn.XLOOKUP(B27,Vendor_Master!A:A,Vendor_Master!C:C) -> 45 | M27: =INDEX(Vendor_Master!$C:$C,MATCH(B27,Vendor_Master!$A:$A,0)) -> 45 | N27: =IF(H27>Assumptions!$B$4,"Large","") | O27: =INDEX(Vendor_Master!$B:$B,MATCH(B27,Vendor_Master!$A:$A,0)) -> Professional Fees | P27: =MONTH(D27) -> 2
A28: INV-1027 | B28: Nexus Professional Consultants | C28: Tower A | D28: 2026-02-22 | E28: 2026-04-08 | F28: 88251.77 | G28: 15885.32 | H28: 104137.09 | I28: Paid | J28: 2026-03-22 | K28: =VLOOKUP(B28,Vendor_Master!$A:$C,3,FALSE()) -> 45 | L28: =_xlfn.XLOOKUP(B28,Vendor_Master!A:A,Vendor_Master!C:C) -> 45 | M28: =INDEX(Vendor_Master!$C:$C,MATCH(B28,Vendor_Master!$A:$A,0)) -> 45 | N28: =IF(H28>Assumptions!$B$4,"Large","") -> Large | O28: =INDEX(Vendor_Master!$B:$B,MATCH(B28,Vendor_Master!$A:$A,0)) -> Professional Fees | P28: =MONTH(D28) -> 2
A29: INV-1028 | B29: Apex Security Solutions | C29: Commercial Block | D29: 2026-02-23 | E29: 2026-03-25 | F29: 84448.8 | G29: 15200.78 | H29: 99649.58 | I29: Paid | J29: 2026-03-07 | K29: =VLOOKUP(B29,Vendor_Master!$A:$C,3,FALSE()) -> 30 | L29: =_xlfn.XLOOKUP(B29,Vendor_Master!A:A,Vendor_Master!C:C) -> 30 | M29: =INDEX(Vendor_Master!$C:$C,MATCH(B29,Vendor_Master!$A:$A,0)) -> 30 | N29: =IF(H29>Assumptions!$B$4,"Large","") -> Large | O29: =INDEX(Vendor_Master!$B:$B,MATCH(B29,Vendor_Master!$A:$A,0)) -> Security | P29: =MONTH(D29) -> 2
A30: INV-1029 | B30: UrbanEdge Marketing | C30: Retail Plaza | D30: 2026-02-14 | E30: 2026-03-16 | F30: 15451.85 | G30: 2781.33 | H30: 18233.18 | I30: Overdue | K30: =VLOOKUP(B30,Vendor_Master!$A:$C,3,FALSE()) -> 30 | L30: =_xlfn.XLOOKUP(B30,Vendor_Master!A:A,Vendor_Master!C:C) -> 30 | M30: =INDEX(Vendor_Master!$C:$C,MATCH(B30,Vendor_Master!$A:$A,0)) -> 30 | N30: =IF(H30>Assumptions!$B$4,"Large","") | O30: =INDEX(Vendor_Master!$B:$B,MATCH(B30,Vendor_Master!$A:$A,0)) -> Marketing | P30: =MONTH(D30) -> 2
A31: INV-1030 | B31: Nexus Professional Consultants | C31: Retail Plaza | D31: 2026-03-08 | E31: 2026-04-22 | F31: 18941.16 | G31: 3409.41 | H31: 22350.57 | I31: Overdue | K31: =VLOOKUP(B31,Vendor_Master!$A:$C,3,FALSE()) -> 45 | L31: =_xlfn.XLOOKUP(B31,Vendor_Master!A:A,Vendor_Master!C:C) -> 45 | M31: =INDEX(Vendor_Master!$C:$C,MATCH(B31,Vendor_Master!$A:$A,0)) -> 45 | N31: =IF(H31>Assumptions!$B$4,"Large","") | O31: =INDEX(Vendor_Master!$B:$B,MATCH(B31,Vendor_Master!$A:$A,0)) -> Professional Fees | P31: =MONTH(D31) -> 3
A32: INV-1031 | B32: Clean & Clear Housekeeping | C32: Retail Plaza | D32: 2026-02-20 | E32: 2026-03-07 | F32: 53907.62 | G32: 9703.37 | H32: 63610.99 | I32: Overdue | K32: =VLOOKUP(B32,Vendor_Master!$A:$C,3,FALSE()) -> 15 | L32: =_xlfn.XLOOKUP(B32,Vendor_Master!A:A,Vendor_Master!C:C) -> 15 | M32: =INDEX(Vendor_Master!$C:$C,MATCH(B32,Vendor_Master!$A:$A,0)) -> 15 | N32: =IF(H32>Assumptions!$B$4,"Large","") | O32: =INDEX(Vendor_Master!$B:$B,MATCH(B32,Vendor_Master!$A:$A,0)) -> Housekeeping | P32: =MONTH(D32) -> 2
A33: INV-1032 | B33: Nexus Professional Consultants | C33: Tower B | D33: 2026-03-08 | E33: 2026-04-22 | F33: 71504 | G33: 12870.72 | H33: 84374.72 | I33: Paid | J33: 2026-03-30 | K33: =VLOOKUP(B33,Vendor_Master!$A:$C,3,FALSE()) -> 45 | L33: =_xlfn.XLOOKUP(B33,Vendor_Master!A:A,Vendor_Master!C:C) -> 45 | M33: =INDEX(Vendor_Master!$C:$C,MATCH(B33,Vendor_Master!$A:$A,0)) -> 45 | N33: =IF(H33>Assumptions!$B$4,"Large","") -> Large | O33: =INDEX(Vendor_Master!$B:$B,MATCH(B33,Vendor_Master!$A:$A,0)) -> Professional Fees | P33: =MONTH(D33) -> 3
A34: INV-1033 | B34: SafeGuard Fire & Safety | C34: Retail Plaza | D34: 2026-03-04 | E34: 2026-04-03 | F34: 40487.58 | G34: 7287.76 | H34: 47775.34 | I34: Paid | J34: 2026-03-15 | K34: =VLOOKUP(B34,Vendor_Master!$A:$C,3,FALSE()) -> 30 | L34: =_xlfn.XLOOKUP(B34,Vendor_Master!A:A,Vendor_Master!C:C) -> 30 | M34: =INDEX(Vendor_Master!$C:$C,MATCH(B34,Vendor_Master!$A:$A,0)) -> 30 | N34: =IF(H34>Assumptions!$B$4,"Large","") | O34: =INDEX(Vendor_Master!$B:$B,MATCH(B34,Vendor_Master!$A:$A,0)) -> Maintenance | P34: =MONTH(D34) -> 3
A35: INV-1034 | B35: Reliable Repairs Co | C35: Tower B | D35: 2026-02-26 | E35: 2026-03-28 | F35: 59182.86 | G35: 10652.91 | H35: 69835.77 | I35: Paid | J35: 2026-02-27 | K35: =VLOOKUP(B35,Vendor_Master!$A:$C,3,FALSE()) -> 30 | L35: =_xlfn.XLOOKUP(B35,Vendor_Master!A:A,Vendor_Master!C:C) -> 30 | M35: =INDEX(Vendor_Master!$C:$C,MATCH(B35,Vendor_Master!$A:$A,0)) -> 30 | N35: =IF(H35>Assumptions!$B$4,"Large","") | O35: =INDEX(Vendor_Master!$B:$B,MATCH(B35,Vendor_Master!$A:$A,0)) -> Repairs | P35: =MONTH(D35) -> 2
A36: INV-1035 | B36: Apex Security Solutions | C36: Tower B | D36: 2026-03-20 | E36: 2026-04-19 | F36: 62905.96 | G36: 11323.07 | H36: 74229.03 | I36: Paid | J36: 2026-03-21 | K36: =VLOOKUP(B36,Vendor_Master!$A:$C,3,FALSE()) -> 30 | L36: =_xlfn.XLOOKUP(B36,Vendor_Master!A:A,Vendor_Master!C:C) -> 30 | M36: =INDEX(Vendor_Master!$C:$C,MATCH(B36,Vendor_Master!$A:$A,0)) -> 30 | N36: =IF(H36>Assumptions!$B$4,"Large","") -> Large | O36: =INDEX(Vendor_Master!$B:$B,MATCH(B36,Vendor_Master!$A:$A,0)) -> Security | P36: =MONTH(D36) -> 3
A37: INV-1036 | B37: Reliable Repairs Co | C37: Commercial Block | D37: 2026-02-28 | E37: 2026-03-30 | F37: 52731.58 | G37: 9491.68 | H37: 62223.26 | I37: Paid | J37: 2026-03-10 | K37: =VLOOKUP(B37,Vendor_Master!$A:$C,3,FALSE()) -> 30 | L37: =_xlfn.XLOOKUP(B37,Vendor_Master!A:A,Vendor_Master!C:C) -> 30 | M37: =INDEX(Vendor_Master!$C:$C,MATCH(B37,Vendor_Master!$A:$A,0)) -> 30 | N37: =IF(H37>Assumptions!$B$4,"Large","") | O37: =INDEX(Vendor_Master!$B:$B,MATCH(B37,Vendor_Master!$A:$A,0)) -> Repairs | P37: =MONTH(D37) -> 2
A38: INV-1037 | B38: Nexus Professional Consultants | C38: Retail Plaza | D38: 2026-03-02 | E38: 2026-04-16 | F38: 70931.67 | G38: 12767.7 | H38: 83699.37 | I38: Paid | J38: 2026-03-29 | K38: =VLOOKUP(B38,Vendor_Master!$A:$C,3,FALSE()) -> 45 | L38: =_xlfn.XLOOKUP(B38,Vendor_Master!A:A,Vendor_Master!C:C) -> 45 | M38: =INDEX(Vendor_Master!$C:$C,MATCH(B38,Vendor_Master!$A:$A,0)) -> 45 | N38: =IF(H38>Assumptions!$B$4,"Large","") -> Large | O38: =INDEX(Vendor_Master!$B:$B,MATCH(B38,Vendor_Master!$A:$A,0)) -> Professional Fees | P38: =MONTH(D38) -> 3
A39: INV-1038 | B39: Capital Insurance Brokers | C39: Retail Plaza | D39: 2026-03-04 | E39: 2026-04-18 | F39: 16206.34 | G39: 2917.14 | H39: 19123.48 | I39: Paid | J39: 2026-03-27 | K39: =VLOOKUP(B39,Vendor_Master!$A:$C,3,FALSE()) -> 45 | L39: =_xlfn.XLOOKUP(B39,Vendor_Master!A:A,Vendor_Master!C:C) -> 45 | M39: =INDEX(Vendor_Master!$C:$C,MATCH(B39,Vendor_Master!$A:$A,0)) -> 45 | N39: =IF(H39>Assumptions!$B$4,"Large","") | O39: =INDEX(Vendor_Master!$B:$B,MATCH(B39,Vendor_Master!$A:$A,0)) -> Insurance | P39: =MONTH(D39) -> 3
A40: INV-1039 | B40: BrightWay Office Supplies | C40: Tower A | D40: 2026-03-25 | E40: 2026-04-09 | F40: 71429.6 | G40: 12857.33 | H40: 84286.93 | I40: Paid | J40: 2026-04-14 | K40: =VLOOKUP(B40,Vendor_Master!$A:$C,3,FALSE()) -> 15 | L40: =_xlfn.XLOOKUP(B40,Vendor_Master!A:A,Vendor_Master!C:C) -> 15 | M40: =INDEX(Vendor_Master!$C:$C,MATCH(B40,Vendor_Master!$A:$A,0)) -> 15 | N40: =IF(H40>Assumptions!$B$4,"Large","") -> Large | O40: =INDEX(Vendor_Master!$B:$B,MATCH(B40,Vendor_Master!$A:$A,0)) -> Office Supplies | P40: =MONTH(D40) -> 3
...

Sheet PivotTable_Analysis
A3: Sum of Total_Amount | B3: Payment_Status
A4: Category_Lookup | B4: Overdue | C4: Paid | D4: Pending | E4: Total Result
A5: Housekeeping | B5: 176514.52 | C5: 383814.6 | D5: 107784.8 | E5: 668113.92
A6: Insurance | B6: 69289.95 | C6: 192487.37 | D6: 127640.72 | E6: 389418.04
A7: Landscaping | B7: 11947.51 | C7: 458479.15 | D7: 90106 | E7: 560532.66
A8: Maintenance | B8: 202823.68 | C8: 927746 | D8: 29400.73 | E8: 1159970.4
A9: Marketing | B9: 18233.18 | C9: 119719.48 | D9: 128668.63 | E9: 266621.29
A10: Office Supplies | B10: 31378.58 | C10: 226557.38 | E10: 257935.96
A11: Professional Fees | B11: 111661.83 | C11: 652777.28 | D11: 158639.52 | E11: 923078.63
A12: Repairs | B12: 61735.58 | C12: 504788.32 | E12: 566523.9
A13: Security | B13: 93918.83 | C13: 390893.44 | D13: 53441.39 | E13: 538253.66
A14: Utilities | B14: 31985.69 | C14: 488193.49 | D14: 102342.02 | E14: 622521.2
A15: Total Result | B15: 809489.35 | C15: 4345456.5 | D15: 798023.81 | E15: 5952969.7

Sheet Summary
A1: Monthly Spend by Category (Total_Amount)
A2: Category | B2: Jan | C2: Feb | D2: Mar | E2: Apr | F2: May | G2: Jun
A3: Housekeeping | B3: =SUMIFS(Raw_Data!$H$2:$H$104,Raw_Data!$O$2:$O$104,$A3,Raw_Data!$P$2:$P$104,1) -> 0 | C3: =SUMIFS(Raw_Data!$H$2:$H$104,Raw_Data!$O$2:$O$104,$A3,Raw_Data!$P$2:$P$104,2) -> 176514.52 | D3: =SUMIFS(Raw_Data!$H$2:$H$104,Raw_Data!$O$2:$O$104,$A3,Raw_Data!$P$2:$P$104,3) -> 70526.3 | E3: =SUMIFS(Raw_Data!$H$2:$H$104,Raw_Data!$O$2:$O$104,$A3,Raw_Data!$P$2:$P$104,4) -> 0 | F3: =SUMIFS(Raw_Data!$H$2:$H$104,Raw_Data!$O$2:$O$104,$A3,Raw_Data!$P$2:$P$104,5) -> 200075.68 | G3: =SUMIFS(Raw_Data!$H$2:$H$104,Raw_Data!$O$2:$O$104,$A3,Raw_Data!$P$2:$P$104,6) -> 220997.42
A4: Insurance | B4: =SUMIFS(Raw_Data!$H$2:$H$104,Raw_Data!$O$2:$O$104,$A4,Raw_Data!$P$2:$P$104,1) -> 55555.8 | C4: =SUMIFS(Raw_Data!$H$2:$H$104,Raw_Data!$O$2:$O$104,$A4,Raw_Data!$P$2:$P$104,2) -> 72507.48 | D4: =SUMIFS(Raw_Data!$H$2:$H$104,Raw_Data!$O$2:$O$104,$A4,Raw_Data!$P$2:$P$104,3) -> 19123.48 | E4: =SUMIFS(Raw_Data!$H$2:$H$104,Raw_Data!$O$2:$O$104,$A4,Raw_Data!$P$2:$P$104,4) -> 13734.15 | F4: =SUMIFS(Raw_Data!$H$2:$H$104,Raw_Data!$O$2:$O$104,$A4,Raw_Data!$P$2:$P$104,5) -> 185088.85 | G4: =SUMIFS(Raw_Data!$H$2:$H$104,Raw_Data!$O$2:$O$104,$A4,Raw_Data!$P$2:$P$104,6) -> 43408.28
A5: Landscaping | B5: =SUMIFS(Raw_Data!$H$2:$H$104,Raw_Data!$O$2:$O$104,$A5,Raw_Data!$P$2:$P$104,1) -> 43994.8 | C5: =SUMIFS(Raw_Data!$H$2:$H$104,Raw_Data!$O$2:$O$104,$A5,Raw_Data!$P$2:$P$104,2) -> 99407.9 | D5: =SUMIFS(Raw_Data!$H$2:$H$104,Raw_Data!$O$2:$O$104,$A5,Raw_Data!$P$2:$P$104,3) -> 120061.11 | E5: =SUMIFS(Raw_Data!$H$2:$H$104,Raw_Data!$O$2:$O$104,$A5,Raw_Data!$P$2:$P$104,4) -> 120544.72 | F5: =SUMIFS(Raw_Data!$H$2:$H$104,Raw_Data!$O$2:$O$104,$A5,Raw_Data!$P$2:$P$104,5) -> 11947.51 | G5: =SUMIFS(Raw_Data!$H$2:$H$104,Raw_Data!$O$2:$O$104,$A5,Raw_Data!$P$2:$P$104,6) -> 164576.62
A6: Maintenance | B6: =SUMIFS(Raw_Data!$H$2:$H$104,Raw_Data!$O$2:$O$104,$A6,Raw_Data!$P$2:$P$104,1) -> 489180.26 | C6: =SUMIFS(Raw_Data!$H$2:$H$104,Raw_Data!$O$2:$O$104,$A6,Raw_Data!$P$2:$P$104,2) -> 107221.69 | D6: =SUMIFS(Raw_Data!$H$2:$H$104,Raw_Data!$O$2:$O$104,$A6,Raw_Data!$P$2:$P$104,3) -> 154507.83 | E6: =SUMIFS(Raw_Data!$H$2:$H$104,Raw_Data!$O$2:$O$104,$A6,Raw_Data!$P$2:$P$104,4) -> 166532.12 | F6: =SUMIFS(Raw_Data!$H$2:$H$104,Raw_Data!$O$2:$O$104,$A6,Raw_Data!$P$2:$P$104,5) -> 104419.59 | G6: =SUMIFS(Raw_Data!$H$2:$H$104,Raw_Data!$O$2:$O$104,$A6,Raw_Data!$P$2:$P$104,6) -> 138108.92
A7: Marketing | B7: =SUMIFS(Raw_Data!$H$2:$H$104,Raw_Data!$O$2:$O$104,$A7,Raw_Data!$P$2:$P$104,1) -> 46565.45 | C7: =SUMIFS(Raw_Data!$H$2:$H$104,Raw_Data!$O$2:$O$104,$A7,Raw_Data!$P$2:$P$104,2) -> 18233.18 | D7: =SUMIFS(Raw_Data!$H$2:$H$104,Raw_Data!$O$2:$O$104,$A7,Raw_Data!$P$2:$P$104,3) -> 0 | E7: =SUMIFS(Raw_Data!$H$2:$H$104,Raw_Data!$O$2:$O$104,$A7,Raw_Data!$P$2:$P$104,4) -> 41918.53 | F7: =SUMIFS(Raw_Data!$H$2:$H$104,Raw_Data!$O$2:$O$104,$A7,Raw_Data!$P$2:$P$104,5) -> 19027.13 | G7: =SUMIFS(Raw_Data!$H$2:$H$104,Raw_Data!$O$2:$O$104,$A7,Raw_Data!$P$2:$P$104,6) -> 140877
A8: Office Supplies | B8: =SUMIFS(Raw_Data!$H$2:$H$104,Raw_Data!$O$2:$O$104,$A8,Raw_Data!$P$2:$P$104,1) -> 0 | C8: =SUMIFS(Raw_Data!$H$2:$H$104,Raw_Data!$O$2:$O$104,$A8,Raw_Data!$P$2:$P$104,2) -> 0 | D8: =SUMIFS(Raw_Data!$H$2:$H$104,Raw_Data!$O$2:$O$104,$A8,Raw_Data!$P$2:$P$104,3) -> 84286.93 | E8: =SUMIFS(Raw_Data!$H$2:$H$104,Raw_Data!$O$2:$O$104,$A8,Raw_Data!$P$2:$P$104,4) -> 0 | F8: =SUMIFS(Raw_Data!$H$2:$H$104,Raw_Data!$O$2:$O$104,$A8,Raw_Data!$P$2:$P$104,5) -> 0 | G8: =SUMIFS(Raw_Data!$H$2:$H$104,Raw_Data!$O$2:$O$104,$A8,Raw_Data!$P$2:$P$104,6) -> 173649.03
A9: Professional Fees | B9: =SUMIFS(Raw_Data!$H$2:$H$104,Raw_Data!$O$2:$O$104,$A9,Raw_Data!$P$2:$P$104,1) -> 0 | C9: =SUMIFS(Raw_Data!$H$2:$H$104,Raw_Data!$O$2:$O$104,$A9,Raw_Data!$P$2:$P$104,2) -> 314113.56 | D9: =SUMIFS(Raw_Data!$H$2:$H$104,Raw_Data!$O$2:$O$104,$A9,Raw_Data!$P$2:$P$104,3) -> 190424.66 | E9: =SUMIFS(Raw_Data!$H$2:$H$104,Raw_Data!$O$2:$O$104,$A9,Raw_Data!$P$2:$P$104,4) -> 23037.99 | F9: =SUMIFS(Raw_Data!$H$2:$H$104,Raw_Data!$O$2:$O$104,$A9,Raw_Data!$P$2:$P$104,5) -> 100142.86 | G9: =SUMIFS(Raw_Data!$H$2:$H$104,Raw_Data!$O$2:$O$104,$A9,Raw_Data!$P$2:$P$104,6) -> 295359.56
A10: Repairs | B10: =SUMIFS(Raw_Data!$H$2:$H$104,Raw_Data!$O$2:$O$104,$A10,Raw_Data!$P$2:$P$104,1) -> 36595.72 | C10: =SUMIFS(Raw_Data!$H$2:$H$104,Raw_Data!$O$2:$O$104,$A10,Raw_Data!$P$2:$P$104,2) -> 243884.49 | D10: =SUMIFS(Raw_Data!$H$2:$H$104,Raw_Data!$O$2:$O$104,$A10,Raw_Data!$P$2:$P$104,3) -> 0 | E10: =SUMIFS(Raw_Data!$H$2:$H$104,Raw_Data!$O$2:$O$104,$A10,Raw_Data!$P$2:$P$104,4) -> 25634.28 | F10: =SUMIFS(Raw_Data!$H$2:$H$104,Raw_Data!$O$2:$O$104,$A10,Raw_Data!$P$2:$P$104,5) -> 260409.41 | G10: =SUMIFS(Raw_Data!$H$2:$H$104,Raw_Data!$O$2:$O$104,$A10,Raw_Data!$P$2:$P$104,6) -> 0
A11: Security | B11: =SUMIFS(Raw_Data!$H$2:$H$104,Raw_Data!$O$2:$O$104,$A11,Raw_Data!$P$2:$P$104,1) -> 141073.97 | C11: =SUMIFS(Raw_Data!$H$2:$H$104,Raw_Data!$O$2:$O$104,$A11,Raw_Data!$P$2:$P$104,2) -> 99649.58 | D11: =SUMIFS(Raw_Data!$H$2:$H$104,Raw_Data!$O$2:$O$104,$A11,Raw_Data!$P$2:$P$104,3) -> 179726.87 | E11: =SUMIFS(Raw_Data!$H$2:$H$104,Raw_Data!$O$2:$O$104,$A11,Raw_Data!$P$2:$P$104,4) -> 36590.08 | F11: =SUMIFS(Raw_Data!$H$2:$H$104,Raw_Data!$O$2:$O$104,$A11,Raw_Data!$P$2:$P$104,5) -> 27771.77 | G11: =SUMIFS(Raw_Data!$H$2:$H$104,Raw_Data!$O$2:$O$104,$A11,Raw_Data!$P$2:$P$104,6) -> 53441.39
A12: Utilities | B12: =SUMIFS(Raw_Data!$H$2:$H$104,Raw_Data!$O$2:$O$104,$A12,Raw_Data!$P$2:$P$104,1) -> 0 | C12: =SUMIFS(Raw_Data!$H$2:$H$104,Raw_Data!$O$2:$O$104,$A12,Raw_Data!$P$2:$P$104,2) -> 31985.69 | D12: =SUMIFS(Raw_Data!$H$2:$H$104,Raw_Data!$O$2:$O$104,$A12,Raw_Data!$P$2:$P$104,3) -> 116037.21 | E12: =SUMIFS(Raw_Data!$H$2:$H$104,Raw_Data!$O$2:$O$104,$A12,Raw_Data!$P$2:$P$104,4) -> 206378.79 | F12: =SUMIFS(Raw_Data!$H$2:$H$104,Raw_Data!$O$2:$O$104,$A12,Raw_Data!$P$2:$P$104,5) -> 77077.61 | G12: =SUMIFS(Raw_Data!$H$2:$H$104,Raw_Data!$O$2:$O$104,$A12,Raw_Data!$P$2:$P$104,6) -> 191041.9
A13: Total | B13: =SUM(B3:B12) -> 812966 | C13: =SUM(C3:C12) -> 1163518.1 | D13: =SUM(D3:D12) -> 934694.39 | E13: =SUM(E3:E12) -> 634370.66 | F13: =SUM(F3:F12) -> 985960.41 | G13: =SUM(G3:G12) -> 1421460.1
A20: Total Spend by Category (overall)
A21: Category | B21: Total_Amount
A22: Housekeeping | B22: =SUMIFS(Raw_Data!$H$2:$H$104,Raw_Data!$O$2:$O$104,$A22) -> 668113.92
A23: Insurance | B23: =SUMIFS(Raw_Data!$H$2:$H$104,Raw_Data!$O$2:$O$104,$A23) -> 389418.04
A24: Landscaping | B24: =SUMIFS(Raw_Data!$H$2:$H$104,Raw_Data!$O$2:$O$104,$A24) -> 560532.66
A25: Maintenance | B25: =SUMIFS(Raw_Data!$H$2:$H$104,Raw_Data!$O$2:$O$104,$A25) -> 1159970.4
A26: Marketing | B26: =SUMIFS(Raw_Data!$H$2:$H$104,Raw_Data!$O$2:$O$104,$A26) -> 266621.29
A27: Office Supplies | B27: =SUMIFS(Raw_Data!$H$2:$H$104,Raw_Data!$O$2:$O$104,$A27) -> 257935.96
A28: Professional Fees | B28: =SUMIFS(Raw_Data!$H$2:$H$104,Raw_Data!$O$2:$O$104,$A28) -> 923078.63
A29: Repairs | B29: =SUMIFS(Raw_Data!$H$2:$H$104,Raw_Data!$O$2:$O$104,$A29) -> 566523.9
A30: Security | B30: =SUMIFS(Raw_Data!$H$2:$H$104,Raw_Data!$O$2:$O$104,$A30) -> 538253.66
A31: Utilities | B31: =SUMIFS(Raw_Data!$H$2:$H$104,Raw_Data!$O$2:$O$104,$A31) -> 622521.2
A35: Filtered Breakdown (auto-updates with Dashboard month selector)
A36: Category | B36: Total_Amount
A37: Housekeeping | B37: =IF(Dashboard!$B$4="All",$B$22,INDEX($B$3:$G$3,1,MATCH(Dashboard!$B$4,{"Jan","Feb","Mar","Apr","May","Jun"},0))) -> 668113.92
A38: Insurance | B38: =IF(Dashboard!$B$4="All",$B$23,INDEX($B$4:$G$4,1,MATCH(Dashboard!$B$4,{"Jan","Feb","Mar","Apr","May","Jun"},0))) -> 389418.04
A39: Landscaping | B39: =IF(Dashboard!$B$4="All",$B$24,INDEX($B$5:$G$5,1,MATCH(Dashboard!$B$4,{"Jan","Feb","Mar","Apr","May","Jun"},0))) -> 560532.66
A40: Maintenance | B40: =IF(Dashboard!$B$4="All",$B$25,INDEX($B$6:$G$6,1,MATCH(Dashboard!$B$4,{"Jan","Feb","Mar","Apr","May","Jun"},0))) -> 1159970.4
A41: Marketing | B41: =IF(Dashboard!$B$4="All",$B$26,INDEX($B$7:$G$7,1,MATCH(Dashboard!$B$4,{"Jan","Feb","Mar","Apr","May","Jun"},0))) -> 266621.29
A42: Office Supplies | B42: =IF(Dashboard!$B$4="All",$B$27,INDEX($B$8:$G$8,1,MATCH(Dashboard!$B$4,{"Jan","Feb","Mar","Apr","May","Jun"},0))) -> 257935.96
A43: Professional Fees | B43: =IF(Dashboard!$B$4="All",$B$28,INDEX($B$9:$G$9,1,MATCH(Dashboard!$B$4,{"Jan","Feb","Mar","Apr","May","Jun"},0))) -> 923078.63
A44: Repairs | B44: =IF(Dashboard!$B$4="All",$B$29,INDEX($B$10:$G$10,1,MATCH(Dashboard!$B$4,{"Jan","Feb","Mar","Apr","May","Jun"},0))) -> 566523.9
A45: Security | B45: =IF(Dashboard!$B$4="All",$B$30,INDEX($B$11:$G$11,1,MATCH(Dashboard!$B$4,{"Jan","Feb","Mar","Apr","May","Jun"},0))) -> 538253.66
A46: Utilities | B46: =IF(Dashboard!$B$4="All",$B$31,INDEX($B$12:$G$12,1,MATCH(Dashboard!$B$4,{"Jan","Feb","Mar","Apr","May","Jun"},0))) -> 622521.2
A60: Live Pivot — Category x Payment Status (auto-updates with month selector)
A61: Category | B61: Paid | C61: Pending | D61: Overdue | E61: Grand Total
A62: Housekeeping | B62: =IF(Dashboard!$B$4="All",SUMIFS(Raw_Data!$H$2:$H$104,Raw_Data!$O$2:$O$104,$A62,Raw_Data!$I$2:$I$104,"Paid"),SUMIFS(Raw_Data!$H$2:$H$104,Raw_Data!$O$2:$O$104,$A62,Raw_Data!$I$2:$I$104,"Paid",Raw_Data!$P$2:$P$104,MATCH(Dashboard!$B$4,{"Jan","Feb","Mar","Apr","May","Jun"},0))) -> 383814.6 | C62: =IF(Dashboard!$B$4="All",SUMIFS(Raw_Data!$H$2:$H$104,Raw_Data!$O$2:$O$104,$A62,Raw_Data!$I$2:$I$104,"Pending"),SUMIFS(Raw_Data!$H$2:$H$104,Raw_Data!$O$2:$O$104,$A62,Raw_Data!$I$2:$I$104,"Pending",Raw_Data!$P$2:$P$104,MATCH(Dashboard!$B$4,{"Jan","Feb","Mar","Apr","May","Jun"},0))) -> 107784.8 | D62: =IF(Dashboard!$B$4="All",SUMIFS(Raw_Data!$H$2:$H$104,Raw_Data!$O$2:$O$104,$A62,Raw_Data!$I$2:$I$104,"Overdue"),SUMIFS(Raw_Data!$H$2:$H$104,Raw_Data!$O$2:$O$104,$A62,Raw_Data!$I$2:$I$104,"Overdue",Raw_Data!$P$2:$P$104,MATCH(Dashboard!$B$4,{"Jan","Feb","Mar","Apr","May","Jun"},0))) -> 176514.52 | E62: =SUM(B62:D62) -> 668113.92
...
